Workbook

Sheet Лист1
A1: Олмазор тумани Тиббиёт Бирлашмаси томонидан 2018 йил ноябрь ойи иш хаки суммалари поликлиникалар кесимида
A2: Ташкилот номи | B2: Суммаси | C2: Санаси | D2: Кабул килди: ФИО | E2: Имзо
A3: 5-Детская стоматологическая поликлиника | B3: 10 182 556,00
A4: 4- Тери Таносил Касалликлар диспансери | B4: 28 122 959,00
A5: Противотуберкулезный диспансер №3 | B5: 32 529 279,00
A6: Олмазор туман Марказий куп тармокли поликлиника | B6: 86830534
A7: 14 Оилавий поликлиника | B7: 30 725 181,00
A8: 15 Семейная поликлиника | B8: 36 774 668,00
A9: 16 Оилавий поликлиника | B9: 51202266
A10: 17-Оилавий поликлиника | B10: 20 644 086,00
A11: 20-сон оилавий поликлиника | B11: 22 068 389,00
A12: 21 - семейная поликлиника | B12: 28 867 178,00
A13: Олмазор туман 18 оилавий поликлиника | B13: 26 166 414,00
A14: Олмазор тумани 19 Оилавий поликлиника | B14: 38 203 767,00
A15: Талабалар шахарчаси Марказий кўптармоқли поликлиника | B15: 24 516 602,00
A16: Жами | B16: 436833879
A18: Бош Хисобчи | B18: Рустамова Ш.С
A20: ТТБ бошлиги | B20: Миралимов М.М

Sheet 11,2018
A1: № | B1: НАИМЕНОВАНИЯ | C1: ИНПС | D1: ЕСП | E1: ПОД НАЛ | F1: ЕНП | G1: ОПЛАТА | H1: БАЛАНС | I1: ФИН РЕЗ | J1: ПЕНСИЯ
A2: 1 | B2: AVTOMOTOHAVASKOR TALABALAR , ИНН: 304651169 | K2: 36275148
A3: 2 | B3: "ASADTILLO BIZNES" ИНН : 304453422 | K3: 13540974 | L3: НДС
A4: 3 | B4: "INSHOOT MAXSUSMONTAJ QURILISH" ИНН : 301716199 | C4: картотека | K4: 33979629 | L4: НДС
A5: 4 | B5: "ЧП ENGLISH SERVICE" ИНН: 303256439 | K5: 72641824 | L5: НДС
A6: 5 | B6: "MUZAFFARXO`JA-HILOL" Х.Ф. ИНН: 206450634 | K6: 84564973 | L6: НДС
A7: 6 | B7: "STUDY GUIDE" ИНН: 303408381 | K7: 45313285
A8: 7 | B8: "ЧП INTER PROF EDUCATION" ИНН: 304107369 | K8: 88700206
A9: 8 | B9: "AVTOMOTOHAVASKORLAR YANGIOBOD" ИНН: 304632864 | K9: 86722119
A10: 9 | B10: "DILFUZAXON AVTO" ИНН: 304825630 | K10: 35324962
A11: 10 | B11: "GLOBALMED" , ИНН: 304979653 | K11: 100186 | L11: НДС
A12: 11 | B12: "УП CHORBOG` AVTOUSTOZ" ИНН: 305133922 | K12: 50995539
A13: 12 | B13: "C A WOLVES" , ИНН: 305713761 | C13: нет ещё | K13: 100186
A14: 13 | B14: "MUXLISA NUR FARM" ИНН: 303004885 | K14: 100186
A15: 14 | B15: "AKJ SEBZOR BO`LIMI" , ИНН: 305150198 | K15: 100186
A16: 15 | B16: ООО "MUBINA RAYONA BUSINESS" ИНН: 305023742 | C16: картотека | K16: 34406143
A17: 16 | B17: "RUSLAN GRAND "ИНН: 303451710 | K17: 23956654
A18: 17 | B18: "GULBAHOR BUSINESS" ИНН: 304737756 | C18: картотека | K18: 100186
A19: 18 | B19: ABSOLUTE STRENGTH NTM , ИНН: 303434754 | C19: картотека | K19: 100186
A20: 19 | B20: "FLY HIGH TICKET" ИНН: 305650493 | C20: картотека | K20: 100186
A21: 20 | B21: "SHINEART MCHJ" ИНН: 300821821 | C21: картотека | K21: 100186
A22: 21 | B22: ЯТТ 537852647 Акрамов | C22: керакмас | K22: 100186
A23: 22 | B23: "MCHJ "METCOM" VAKOLATXONASI" ИНН: 207285442, | K23: 100186

Sheet 01,2019
A1: № | B1: НАИМЕНОВАНИЯ | C1: ЕСП и Подоход и ИНПС | D1: 10604-2 вода | E1: 10201-9 прибыль | F1: 10401-6,7 Имущество | G1: 10507-1 Земля | H1: ЕНП, НДС | I1: ОПЛАТА | J1: БАЛАНС | K1: ФИН РЕЗ
A2: 1 | B2: AVTOMOTOHAVASKOR TALABALAR , ИНН: 304651169 | L2: 36275148
A3: 2 | B3: "ASADTILLO BIZNES" ИНН : 304453422 | L3: 13540974 | M3: НДС
A4: 3 | B4: "INSHOOT MAXSUSMONTAJ QURILISH" ИНН : 301716199 | L4: 33979629 | M4: НДС
A5: 4 | B5: "ЧП ENGLISH SERVICE" ИНН: 303256439 | L5: 72641824 | M5: НДС
A6: 5 | B6: "MUZAFFARXO`JA-HILOL" Х.Ф. ИНН: 206450634 | L6: 84564973 | M6: НДС
A7: 6 | B7: "STUDY GUIDE" ИНН: 303408381 | L7: 45313285
A8: 7 | B8: "ЧП INTER PROF EDUCATION" ИНН: 304107369 | L8: 88700206
A9: 8 | B9: "AVTOMOTOHAVASKORLAR YANGIOBOD" ИНН: 304632864 | L9: 86722119
A10: 9 | B10: "DILFUZAXON AVTO" ИНН: 304825630 | L10: 35324962
A11: 10 | B11: "GLOBALMED" , ИНН: 304979653 | L11: 100186 | M11: НДС
A12: 11 | B12: "MEDICOM" ИНН:305925047 | L12: 100186
A13: 12 | B13: "УП CHORBOG` AVTOUSTOZ" ИНН: 305133922 | L13: 50995539
A14: 13 | B14: "C A WOLVES" , ИНН: 305713761 | L14: 100186
A15: 14 | B15: "MUXLISA NUR FARM" ИНН: 303004885 | L15: 100186
A16: 15 | B16: "AKJ SEBZOR BO`LIMI" , ИНН: 305150198 | L16: 100186
A17: 16 | B17: ООО "MUBINA RAYONA BUSINESS" ИНН: 305023742 | L17: 34406143
A18: 17 | B18: "RUSLAN GRAND "ИНН: 303451710 | D18: суммали | F18: суммали | G18: суммали | L18: 23956654
A19: 18 | B19: ЯТТ 537852647 Акрамов | L19: 100186
A20: 19 | B20: "MCHJ "METCOM" VAKOLATXONASI" ИНН: 20728544 | L20: 100186
A21: 20 | B21: "ТСТ CLUSTER" 305904904 | L21: 100186
A22: 21 | B22: "WALL STREET ACADEMY" 306116238 | L22: 100186
A23: 22

Sheet 12,2018 
A1: № | B1: НАИМЕНОВАНИЯ | C1: ИНПС | D1: ЕСП | E1: 10604-2 вода | F1: 10201-9 прибыль | G1: 10401-6,7 Имущество | H1: 10507-1 Земля | I1: ПОД НАЛ | J1: ЕНП | K1: ОПЛАТА | L1: БАЛАНС | M1: ФИН РЕЗ
A2: 1 | B2: AVTOMOTOHAVASKOR TALABALAR , ИНН: 304651169 | N2: 36275148
A3: 2 | B3: "ASADTILLO BIZNES" ИНН : 304453422 | N3: 13540974 | O3: НДС
A4: 3 | B4: "INSHOOT MAXSUSMONTAJ QURILISH" ИНН : 301716199 | C4: картотека | N4: 33979629 | O4: НДС
A5: 4 | B5: "ЧП ENGLISH SERVICE" ИНН: 303256439 | N5: 72641824 | O5: НДС
A6: 5 | B6: "MUZAFFARXO`JA-HILOL" Х.Ф. ИНН: 206450634 | N6: 84564973 | O6: НДС
A7: 6 | B7: "STUDY GUIDE" ИНН: 303408381 | N7: 45313285
A8: 7 | B8: "ЧП INTER PROF EDUCATION" ИНН: 304107369 | N8: 88700206
A9: 8 | B9: "AVTOMOTOHAVASKORLAR YANGIOBOD" ИНН: 304632864 | N9: 86722119
A10: 9 | B10: "DILFUZAXON AVTO" ИНН: 304825630 | N10: 35324962
A11: 10 | B11: "GLOBALMED" , ИНН: 304979653 | N11: 100186 | O11: НДС
A12: 11 | B12: "УП CHORBOG` AVTOUSTOZ" ИНН: 305133922 | N12: 50995539
A13: 12 | B13: "C A WOLVES" , ИНН: 305713761 | C13: нет ещё | N13: 100186
A14: 13 | B14: "MUXLISA NUR FARM" ИНН: 303004885 | N14: 100186
A15: 14 | B15: "AKJ SEBZOR BO`LIMI" , ИНН: 305150198 | N15: 100186
A16: 15 | B16: ООО "MUBINA RAYONA BUSINESS" ИНН: 305023742 | C16: картотека | N16: 34406143
A17: 16 | B17: "RUSLAN GRAND "ИНН: 303451710 | E17: суммали | G17: суммали | H17: суммали | N17: 23956654
A18: 18 | B18: "MCHJ "METCOM" VAKOLATXONASI" ИНН: 20728544 | N18: 100186
A19: 19 | B19: "WALL STREET ACADEMY " 306116238
A20: 17 | B20: ЯТТ 537852647 Акрамов | C20: керакмас | N20: 100186

Sheet 25-29
B1: ЯНВАР | C1: ФЕВРАЛ | D1: МАРТ | E1: АПРЕЛЬ | F1: МАЙ | G1: ИЮНЬ | H1: ИЮЛЬ | I1: АВГУСТ | J1: СЕНТЯБРЬ | K1: ОКТЯБРЬ | L1: НОЯБРЬ | M1: ДЕКАБРЬ
A2: ПОДОХОД 25
A3: ПЕНСИЯ 25
A4: ПОДОХОД 29
A5: ПЕНСИЯ 29
A8: 100186

Sheet клиенты НДС
A1: № | B1: НАИМЕНОВАНИЯ | C1: ИНН | D1: эгаси | F1: сабаб
A2: 1 | B2: ЧП "MATYUSUF SALAEV" | C2: 206155668 | D2: Розия | F2: Охирги ўн икки ой ичида солиқ ҳисоботларини ўз вақтида тақдим этмаслик ҳолатлари мавжуд бўлганлиги
A3: 2 | B3: "MUZAFFARXO`JA-HILOL" Х.Ф. | C3: 206450634 | D3: Ёркиной
A4: 3 | B4: "SHIRIN LYUKS TAOM" 01.09.2021 | C4: 302813323 | D4: Ёркиной
A5: 4 | B5: "STUDY GUIDE" | C5: 303408381 | D5: Розия
A6: 5 | B6: "ЧП INTER PROF EDUCATION" | C6: 304107369 | D6: Розия
A7: 6 | B7: DORKOMPLEKTSNAB PLUS | C7: 304384359 | D7: Ёркиной | F7: Охирги ўн икки ой ичида солиқ ҳисоботларини ўз вақтида тақдим этмаслик ҳолатлари мавжуд бўлганлиги
A8: 7 | B8: MIRIRMONTAJ MCHJ | C8: 304459144 | D8: Ёркиной | F8: Охирги ўн икки ой ичида солиқ ҳисоботларини ўз вақтида тақдим этмаслик ҳолатлари мавжуд бўлганлиги
A9: 8 | B9: "AVTOMOTOHAVASKORLAR YANGIOBOD" | C9: 304632864 | D9: Розия | F9: Охирги ўн икки ой ичида солиқ ҳисоботларини ўз вақтида тақдим этмаслик ҳолатлари мавжуд бўлганлиги
A10: 9 | B10: "FLY TOURISM" | C10: 304801376 | D10: Розия
A11: 10 | B11: "DILFUZAXON AVTO" | C11: 304825630 | D11: Розия | F11: Охирги ўн икки ой ичида солиқ ҳисоботларини ўз вақтида тақдим этмаслик ҳолатлари мавжуд бўлганлиги
A12: 11 | B12: AVTOHAVASKOR CHORSU | C12: 305099119 | D12: Розия | F12: Охирги ўн икки ой ичида солиқ ҳисоботларини ўз вақтида тақдим этмаслик ҳолатлари мавжуд бўлганлиги
A13: 12 | B13: "УП CHORBOG` AVTOUSTOZ" | C13: 305133922 | D13: Розия | F13: Охирги ўн икки ой ичида солиқ ҳисоботларини ўз вақтида тақдим этмаслик ҳолатлари мавжуд бўлганлиги
A14: 13 | B14: "AKJ SEBZOR BO`LIMI" | C14: 305150198 | D14: Розия | F14: Охирги ўн икки ой ичида солиқ ҳисоботларини ўз вақтида тақдим этмаслик ҳолатлари мавжуд бўлганлиги
A15: 14 | B15: "TRANS SERVIS UK" YUNUSOBOD | C15: 305502390 | D15: Розия
A16: 15 | B16: "LANGUAGE ACADEMY" | C16: 305610162 | D16: Розия
A17: 16 | B17: ЧП "PREMIUM TRADING INVEST" | C17: 305630035 | D17: Ёркиной | F17: Охирги ўн икки ой ичида солиқ ҳисоботларини ўз вақтида тақдим этмаслик ҳолатлари мавжуд бўлганлиги
A18: 17 | B18: "C A WOLVES" | C18: 305713761 | D18: Розия | F18: Охирги ўн икки ой ичида солиқ ҳисоботларини ўз вақтида тақдим этмаслик ҳолатлари мавжуд бўлганлиги
A19: 18 | B19: "AVTO DRIVE AKJ" NTM QATORTOL | C19: 305804094 | D19: Розия
A20: 19 | B20: ЧП "MASHXUR TAOM BIZNES" | C20: 305883924 | D20: Ёркиной | F20: Уч ойдан ортиқ вақт давомида молия-хўжалик фаолияти амалга оширилмаганлиги
A21: 20 | B21: HILOL PHARM | C21: 305979201 | D21: Ёркиной | F21: Ходимлари ёки ёлланма ишчилари сони 4 кишидан кам бўлганлиги
A22: 21 | B22: "WALL STREET ACADEMY" | C22: 306116238 | D22: Розия
A23: 22 | B23: "TEACHER`S AUTO SCHOOL" | C23: 306166287 | D23: Розия
A24: 23 | B24: "AVTO SCHOOL" NTM QORAQAMISH | C24: 306214227 | D24: Розия
A25: 24 | B25: " SAM INC" | C25: 306349905 | D25: Ёркиной | F25: Ходимлари ёки ёлланма ишчилари сони 4 кишидан кам бўлганлиги
A26: 25 | B26: "AVTO BEST STUDY" NTM SERGELI | C26: 306372744 | D26: Розия
A27: 26 | B27: "AVTO DRIVE ELEGANT" NTM RISIVIY | C27: 306382810 | D27: Розия
A28: 27 | B28: "LIVING STONE" МЧЖ | C28: 306700191 | D28: Ёркиной | F28: Ходимлари ёки ёлланма ишчилари сони 4 кишидан кам бўлганлиги
A29: 28 | B29: ДОО "KIDS NUR CITY" | C29: 306774385 | D29: Розия
A30: 29 | B30: "AL-AZIZ ACADEMY" НОУ | C30: 306784151 | D30: Розия
A31: 30 | B31: "ZIP LINE" | C31: 306865683 | D31: Ёркиной | F31: Солиқ тўловчининг раҳбари бир вақтнинг ўзида бошқа солиқ тўловчида (юридик шахсда) раҳбар бўлиб, ушбу солиқ тўловчида солиқ қарзи мавжуд бўлганда ёхуд солиқ ҳисоботларини тақдим этилмаганлиги
A32: 31 | B32: ЧП "LIGHT-MED" | C32: 306911088 | D32: Ёркиной | F32: Ходимлари ёки ёлланма ишчилари сони 4 кишидан кам бўлганлиги
A33: 32 | B33: OOO "SS-MOBILE ELECTRONICS" | C33: 306924332 | D33: Ёркиной
A34: 33 | B34: DAMBO STORY MCHJ | C34: 307051200 | D34: Ёркиной | F34: Охирги ўн икки ой ичида солиқ ҳисоботларини ўз вақтида тақдим этмаслик ҳолатлари мавжуд бўлганлиги
A35: 34 | B35: ООО "INTEST MAX" | C35: 307058508 | D35: Розия | F35: Охирги ўн икки ой ичида солиқ ҳисоботларини ўз вақтида тақдим этмаслик ҳолатлари мавжуд бўлганлиги
A36: 35 | B36: "MOVAROUNNAHR BIZNES" INTEGRO | C36: 307101819 | D36: Розия
A37: 36 | B37: ООО "BASKETBALL ACADEMY" | C37: 307205799 | D37: Розия | F37: Ходимлари ёки ёлланма ишчилари сони 4 кишидан кам бўлганлиги
A38: 37 | B38: ООО "ZAMBAR-PLATINUM" | C38: 307209437 | D38: Ёркиной | F38: Ходимлари ёки ёлланма ишчилари сони 4 кишидан кам бўлганлиги
A39: 38 | B39: ООО "HIGH-TECH GROUP" | C39: 307446998 | D39: Ёркиной | F39: Ходимлари ёки ёлланма ишчилари сони 4 кишидан кам бўлганлиги
A40: 39 | B40: "AVIA GORODOK" | C40: 307688389 | D40: Ёркиной
...

Sheet bugalter oylik
A3: Названия строк | B3: Сумма по полю % бухгалтер
A4: Abrorbek | B4: 7040000
A5: Axmadjon | B5: 0
A6: Go'zaloy | B6: 8134000
A7: Maxmuda | B7: 7320000
A8: Mirabbos | B8: 5080000
A9: Muslimbek | B9: 9740000
A10: Sherzod | B10: 100000
A11: (пусто) | B11: 0
A12: Zamira | B12: 8280000
A13: Musobek | B13: 13210000
A14: Humora | B14: 7840000
A15: Ilhom | B15: 3000000
... A31: Общий итог | B31: 113674000

Sheet bank klient oylik
A3: Названия строк | B3: Сумма по полю % банк клиент
A4: Azizbek | B4: 8917500
A5: (пусто) | B5: 0
A6: Bekzod | B6: 2750000
A7: Ruslan | B7: 6257500
A8: Abdulaziz | B8: 2030000
A9: Общий итог | B9: 19955000

Sheet nazoratchi
A3: Названия строк | B3: Сумма по полю Назоратчи %
A4: Go'zaloy | B4: 19322500
A5: (пусто) | B5: 0
A6: Muslimbek | B6: 8068500
A7: Musobek | B7: 2400000
A8: Zamira | B8: 0
A9: Общий итог | B9: 29791000

Sheet Royxat
A2: № | B2: НАИМЕНОВАНИЯ | C2: ИНН | D2: НДС | E2: Бухгалтер | F2: bank klient | G2: Столбец7 | H2: Назоратчи | I2: Столбец10 | J2: % банк клиент | K2: % бухгалтер | L2: Ёркиной | M2: Назоратчи %
A3: 1 | B3: MONTAJ TEPLO ENERGO MCHJ | C3: 306033555 | D3: НДС | E3: Sevara | F3: Azizbek | G3: 500000 | H3: Zamira | I3: 20 | J3: =G3*5% -> 25000 | K3: =G3*I3% -> 100000 | L3: =G3*7% -> 35000 | M3: =G3*5% -> 25000
A4: 2 | B4: "FINANCE COUNCIL" MCHJ | C4: 302672452 | E4: Ruslan | F4: Ruslan | G4: 700000 | H4: Go'zaloy | I4: 20 | J4: =G4*5% -> 35000 | K4: =G4*I4% -> 140000 | L4: =G4*7% -> 49000 | M4: =G4*5% -> 35000
A5: 3 | B5: "ЧП "ROAD RIDERS" | C5: 306807944 | E5: Abrorbek | F5: Ruslan | G5: 700000 | H5: Go'zaloy | I5: 20 | J5: =G5*5% -> 35000 | K5: =G5*I5% -> 140000 | L5: =G5*7% -> 49000 | M5: =G5*5% -> 35000
A6: 4 | B6: ЧП "SEVEN`S UP" | C6: 306918663 | E6: Ruslan | F6: Ruslan | G6: 700000 | H6: Go'zaloy | I6: 20 | J6: =G6*5% -> 35000 | K6: =G6*I6% -> 140000 | L6: =G6*7% -> 49000 | M6: =G6*5% -> 35000
A7: 5 | B7: ООО "TEN BRANCHES" | C7: 307053253 | E7: Go'zaloy | G7: 0 | H7: Muslimbek | I7: 20 | J7: 0 | K7: =G7*I7% -> 0 | L7: =G7*7% -> 0 | M7: =G7*5% -> 0
A8: 6 | B8: СП "ZIL-BAX" | C8: 307972154 | E8: Mohirbek | F8: Ruslan | G8: 700000 | H8: Musobek | I8: 20 | J8: =G8*5% -> 35000 | K8: =G8*I8% -> 140000 | L8: =G8*7% -> 49000 | M8: =G8*5% -> 35000
A9: 7 | B9: OOO "SARDORBEK HOUSE" | C9: 308435425 | E9: Ruslan | F9: Ruslan | G9: 700000 | H9: Go'zaloy | I9: 20 | J9: =G9*5% -> 35000 | K9: =G9*I9% -> 140000 | L9: =G9*7% -> 49000 | M9: =G9*5% -> 35000
A10: 8 | B10: "DILFUZAXON AVTO" | C10: 304825630 | D10: НДС | E10: Abrorbek | F10: Ruslan | G10: 2000000 | H10: Go'zaloy | I10: 20 | J10: =G10*5% -> 100000 | K10: =G10*I10% -> 400000 | L10: =G10*7% -> 140000 | M10: =G10*5% -> 100000
A11: 9 | B11: "SOF MEDTEX" MCHJ | C11: 309899654 | E11: Maxmuda | F11: Azizbek | G11: 6000000 | H11: Go'zaloy | I11: 20 | J11: =G11*5% -> 300000 | K11: =G11*I11% -> 1200000 | L11: =G11*7% -> 420000 | M11: =G11*5% -> 300000
A12: 10 | B12: OOO "RONICS" | C12: 308023653 | D12: НДС | E12: Muslimbek | F12: Azizbek | G12: 2500000 | H12: Go'zaloy | I12: 20 | J12: =G12*5% -> 125000 | K12: =G12*I12% -> 500000 | L12: =G12*7% -> 175000 | M12: =G12*5% -> 125000
A13: 11 | B13: "SAPRAMTECH" OOO | C13: 308820248 | D13: НДС | E13: Muslimbek | F13: Azizbek | G13: 7000000 | H13: Go'zaloy | I13: 20 | J13: =G13*5% -> 350000 | K13: =G13*I13% -> 1400000 | L13: =G13*7% -> 490000 | M13: =G13*5% -> 350000
A14: 12 | B14: GELECTRONIC | C14: 310055812 | D14: НДС | E14: Mirabbos | F14: Ruslan | G14: 4000000 | H14: Muslimbek | I14: 20 | J14: =G14*5% -> 200000 | K14: =G14*I14% -> 800000 | L14: =G14*7% -> 280000 | M14: =G14*5% -> 200000
A15: 13 | B15: SHIRIN XK | C15: 202536307 | D15: НДС | E15: Go'zaloy | G15: 2000000 | H15: Muslimbek | I15: 25 | J15: 0 | K15: =G15*I15% -> 500000 | L15: =G15*7% -> 140000 | M15: =G15*5% -> 100000
A16: 14 | B16: MELIOMASH | C16: 304940229 | D16: НДС | E16: Go'zaloy | G16: 0 | H16: Muslimbek | I16: 20 | J16: 0 | K16: =G16*I16% -> 0 | L16: =G16*7% -> 0 | M16: =G16*5% -> 0
A17: 15 | B17: "C A WOLVES" | C17: 305713761 | D17: НДС | E17: Abdugani | F17: Azizbek | G17: 3000000 | H17: Muslimbek | I17: 20 | J17: =G17*5% -> 150000 | K17: =G17*I17% -> 600000 | L17: =G17*7% -> 210000 | M17: =G17*5% -> 150000
A18: 16 | B18: "AL-AZIZ ACADEMY" НОУ | C18: 306784151 | D18: НДС | E18: Musobek | F18: Azizbek | G18: 3500000 | H18: Go'zaloy | I18: 20 | J18: =G18*5% -> 175000 | K18: =G18*I18% -> 700000 | L18: =G18*7% -> 245000 | M18: =G18*5% -> 175000
A19: 17 | B19: ООО "INTEST MAX" | C19: 307058508 | D19: НДС | E19: Go'zaloy | F19: Azizbek | G19: 25000000 | H19: Muslimbek | I19: 20 | J19: =G19*5% -> 1250000 | K19: =G19*I19% -> 5000000 | L19: =G19*7% -> 1750000 | M19: =G19*5% -> 1250000
A20: 18 | B20: "AVIA GORODOK" | C20: 307688389 | D20: НДС | E20: Mohirbek | F20: Ruslan | G20: 1000000 | H20: Musobek | I20: 20 | J20: =G20*5% -> 50000 | K20: =G20*I20% -> 200000 | L20: =G20*7% -> 70000 | M20: =G20*5% -> 50000
A21: 19 | B21: "AVTOMATLASHTIRILGAN ELEKTRIK YURITMA" | C21: 201250775 | E21: Sevara | G21: 500000 | H21: Zamira | I21: 20 | J21: 0 | K21: =G21*I21% -> 100000 | L21: =G21*7% -> 35000 | M21: =G21*5% -> 25000
A22: 20 | B22: BM UNIT | E22: Humora | F22: Azizbek | G22: 1000000 | H22: Go'zaloy | I22: 20 | J22: =G22*5% -> 50000 | K22: =G22*I22% -> 200000 | L22: =G22*7% -> 70000 | M22: =G22*5% -> 50000
A23: 21 | B23: ООО "AVTO LUXUSARY TRADE" | C23: 307043621 | E23: Alisher | F23: Ruslan | G23: 1000000 | H23: Muslimbek | I23: 20 | J23: =G23*5% -> 50000 | K23: =G23*I23% -> 200000 | L23: =G23*7% -> 70000 | M23: =G23*5% -> 50000
A24: 22 | B24: KOLBERG PRODUCTION | G24: 50000000 | K24: =G24*I24% -> 0 | L24: =G24*5% -> 2500000 | M24: 0
A25: 23 | B25: "AKJ SEBZOR BO`LIMI" | C25: 305150198 | D25: НДС | E25: Sevara | F25: Ruslan | G25: 500000 | H25: Zamira | I25: 20 | J25: =G25*5% -> 25000 | K25: =G25*I25% -> 100000 | L25: =G25*7% -> 35000 | M25: =G25*5% -> 25000
A26: 24 | B26: "AKJ TUZEL BO`LIMI" | C26: 307829726 | D26: НДС | E26: Sevara | F26: Ruslan | G26: 500000 | H26: Zamira | I26: 20 | J26: =G26*5% -> 25000 | K26: =G26*I26% -> 100000 | L26: =G26*7% -> 35000 | M26: =G26*5% -> 25000
A27: 25 | B27: "WALL STREET ACADEMY" | C27: 306116238 | D27: НДС | E27: Maxmuda | F27: Ruslan | G27: 2300000 | H27: Go'zaloy | I27: 20 | J27: =G27*5% -> 115000 | K27: =G27*I27% -> 460000 | L27: =G27*7% -> 161000 | M27: =G27*5% -> 115000
A28: 27 | B28: LIDER ELITE | E28: Zamira | F28: Azizbek | G28: 2500000 | H28: Go'zaloy | I28: 20 | J28: =G28*5% -> 125000 | K28: =G28*I28% -> 500000 | L28: =G28*7% -> 175000 | M28: =G28*5% -> 125000
A29: 28 | B29: NATURE ECO WOOD MCHJ | C29: 309706846 | D29: НДС | E29: Mirabbos | H29: Muslimbek | I29: 20 | J29: 0 | K29: =G29*I29% -> 0 | L29: =G29*7% -> 0 | M29: =G29*5% -> 0
A30: 29 | B30: Wood city 1999 | E30: Mirabbos | H30: Muslimbek | I30: 20 | J30: 0 | K30: =G30*I30% -> 0 | L30: =G30*7% -> 0 | M30: =G30*5% -> 0
A31: 30 | B31: "G-R-A-N-D ELECTRONICS" | C31: 308038910 | E31: Mirabbos | F31: Azizbek | G31: 1000000 | H31: Muslimbek | I31: 20 | J31: =G31*5% -> 50000 | K31: =G31*I31% -> 200000 | L31: =G31*7% -> 70000 | M31: =G31*5% -> 50000
A32: 31 | B32: KIFTI OFTOB SARBONI | E32: Mirabbos | F32: Ruslan | G32: 2000000 | H32: Muslimbek | I32: 20 | J32: =G32*5% -> 100000 | K32: =G32*I32% -> 400000 | L32: =G32*7% -> 140000 | M32: 0
A33: 32 | B33: ЧП "MATYUSUF SALAEV" | C33: 206155668 | D33: НДС | E33: Humora | F33: Azizbek | G33: 0 | H33: Go'zaloy | I33: 20 | J33: =G33*3% -> 0 | K33: =G33*I33% -> 0 | L33: =G33*7% -> 0 | M33: =G33*5% -> 0
A34: 33 | B34: OOO "MAGISTRAL TRANS QURILISH" | C34: 207189989 | D34: НДС | E34: Humora | F34: Ruslan | G34: 3500000 | H34: Go'zaloy | I34: 20 | J34: =G34*5% -> 175000 | K34: =G34*I34% -> 700000 | L34: =G34*7% -> 245000 | M34: =G34*5% -> 175000
A35: 34 | B35: "SHIRIN LYUKS TAOM" 01.09.2021 | C35: 302813323 | D35: НДС | E35: Musobek | G35: 0 | H35: Go'zaloy | I35: 20 | J35: =G35*3% -> 0 | K35: =G35*I35% -> 0 | L35: =G35*7% -> 0 | M35: =G35*5% -> 0
A36: 35 | B36: BY ETIKETKA | E36: Abrorbek | F36: Azizbek | G36: 1500000 | H36: Go'zaloy | I36: 20 | J36: =G36*5% -> 75000 | K36: =G36*I36% -> 300000 | L36: =G36*7% -> 105000 | M36: =G36*5% -> 75000
A37: 36 | B37: IN VITRO PLANTS | E37: Mirabbos | F37: Azizbek | G37: 2000000 | H37: Muslimbek | I37: 20 | J37: =G37*5% -> 100000 | K37: =G37*I37% -> 400000 | L37: =G37*7% -> 140000 | M37: =G37*5% -> 100000
A38: 37 | B38: ООО "BASKETBALL ACADEMY" | C38: 307205799 | D38: НДС | E38: Otabek | F38: Ruslan | G38: 700000 | H38: Muslimbek | I38: 20 | J38: =G38*5% -> 35000 | K38: =G38*I38% -> 140000 | L38: =G38*7% -> 49000 | M38: =G38*5% -> 35000
A39: 38 | B39: "KESH LOGIST" | C39: 307947611 | D39: НДС | E39: Aziz shogird | F39: Ruslan | G39: 500000 | H39: Musobek | I39: 20 | J39: =G39*5% -> 25000 | K39: =G39*I39% -> 100000 | L39: =G39*7% -> 35000 | M39: =G39*5% -> 25000
A40: 39 | B40: "GITA DASTURCHILAR AKADEMIYASI" MCHJ | C40: 309238352 | E40: Dilhush | F40: Azizbek | G40: 1000000 | H40: Go'zaloy | I40: 20 | J40: =G40*5% -> 50000 | K40: =G40*I40% -> 200000 | L40: =G40*7% -> 70000 | M40: =G40*5% -> 50000
A41: 40 | B41: "JS MUROTOV" АДВОКАТЛИК БЮРОСИ" | C41: 207314302 | E41: Maxmuda | F41: Azizbek | G41: 800000 | H41: Go'zaloy | I41: 20 | J41: =G41*5% -> 40000 | K41: =G41*I41% -> 160000 | L41: =G41*7% -> 56000 | M41: =G41*5% -> 40000
...

Sheet 09,2018
A1: № | B1: НАИМЕНОВАНИЯ | C1: ИНПС | D1: ЕСП | E1: ПОД НАЛ | F1: ЕНП | G1: ОПЛАТА | H1: БАЛАНС | I1: ФИН РЕЗ | J1: ПЕНСИЯ
A2: 1 | B2: "MUZAFFARXO`JA-HILOL" Х.Ф. ИНН: 206450634 | K2: 84564973 | L2: 1575434
A3: 2 | B3: "ЧП ENGLISH SERVICE" ИНН: 303256439 | K3: 72641824
A4: 3 | B4: "STUDY GUIDE" ИНН: 303408381 | K4: 45313285
A5: 4 | B5: "ЧП INTER PROF EDUCATION" ИНН: 304107369 | K5: 100186
A6: 5 | B6: "AVTOMOTOHAVASKORLAR YANGIOBOD" ИНН: 304632864 | K6: 86722119
A7: 6 | B7: AVTOMOTOHAVASKOR TALABALAR , ИНН: 304651169 | K7: 36275148
A8: 7 | B8: "DILFUZAXON AVTO" ИНН: 304825630 | K8: 35324962
A9: 8 | B9: "GLOBALMED" , ИНН: 304979653 | K9: 100186
A10: 9 | B10: "УП CHORBOG` AVTOUSTOZ" ИНН: 305133922 | K10: 50995539
A11: 10 | B11: "FLY HIGH TICKET" ИНН: 305650493 | C11: вопросной | K11: 100186
A12: 11 | B12: "RUSLAN GRAND "ИНН: 303451710 | K12: 23956654
A13: 12 | B13: "GULBAHOR BUSINESS" ИНН: 304737756 | C13: картотека | K13: 100186
A14: 13 | B14: "MUXLISA NUR FARM" ИНН: 303004885 | K14: 100186
A15: 14 | B15: "AKJ SEBZOR BO`LIMI" , ИНН: 305150198 | K15: 100186
A16: 15 | B16: "C A WOLVES" , ИНН: 305713761 | C16: нет ещё | K16: 100186
A17: 16 | B17: "ASADTILLO BIZNES" ИНН : 304453422 | K17: 33979629
A18: 17 | B18: "INSHOOT MAXSUSMONTAJ QURILISH" ИНН : 301716199 | C18: картотека | K18: 33979629
A19: 18 | B19: "ООО "MUBINA RAYONA BUSINESS" ИНН: 305023742 | C19: картотека | K19: 34406143
A20: 19 | B20: ABSOLUTE STRENGTH NTM , ИНН: 303434754 | C20: картотека | K20: 100186
A21: 20 | B21: "SHINEART MCHJ" ИНН: 300821821 | C21: картотека | K21: 100186
A22: 21 | B22: "MCHJ "METCOM" VAKOLATXONASI: 505612344 | K22: 14467934
K23: 79026958

Sheet 10,2018 
A1: № | B1: НАИМЕНОВАНИЯ | C1: ИНПС | D1: ЕСП | E1: ПОД НАЛ | F1: ЕНП | G1: ОПЛАТА | H1: БАЛАНС | I1: ФИН РЕЗ | J1: ПЕНСИЯ
A2: 1 | B2: AVTOMOTOHAVASKOR TALABALAR , ИНН: 304651169 | K2: 36275148
A3: 2 | B3: "ASADTILLO BIZNES" ИНН : 304453422 | K3: 13540974
A4: 3 | B4: "INSHOOT MAXSUSMONTAJ QURILISH" ИНН : 301716199 | C4: картотека | K4: 33979629
A5: 4 | B5: "ЧП ENGLISH SERVICE" ИНН: 303256439 | K5: 72641824
A6: 5 | B6: "MUZAFFARXO`JA-HILOL" Х.Ф. ИНН: 206450634 | K6: 84564973
A7: 6 | B7: "STUDY GUIDE" ИНН: 303408381 | K7: 45313285
A8: 7 | B8: "ЧП INTER PROF EDUCATION" ИНН: 304107369 | K8: 88700206
A9: 8 | B9: "AVTOMOTOHAVASKORLAR YANGIOBOD" ИНН: 304632864 | K9: 86722119
A10: 9 | B10: "DILFUZAXON AVTO" ИНН: 304825630 | K10: 35324962
A11: 10 | B11: "GLOBALMED" , ИНН: 304979653 | K11: 100186
A12: 11 | B12: "УП CHORBOG` AVTOUSTOZ" ИНН: 305133922 | K12: 50995539
A13: 12 | B13: "C A WOLVES" , ИНН: 305713761 | C13: нет ещё | K13: 100186
A14: 13 | B14: "MUXLISA NUR FARM" ИНН: 303004885 | K14: 100186
A15: 14 | B15: "AKJ SEBZOR BO`LIMI" , ИНН: 305150198 | K15: 100186
A16: 15 | B16: ООО "MUBINA RAYONA BUSINESS" ИНН: 305023742 | C16: картотека | K16: 34406143
A17: 16 | B17: "RUSLAN GRAND "ИНН: 303451710 | K17: 23956654
A18: 17 | B18: "GULBAHOR BUSINESS" ИНН: 304737756 | C18: картотека | K18: 100186
A19: 18 | B19: ABSOLUTE STRENGTH NTM , ИНН: 303434754 | C19: картотека | K19: 100186
A20: 19 | B20: "FLY HIGH TICKET" ИНН: 305650493 | C20: картотека | K20: 100186
A21: 20 | B21: 300821821 | C21: картотека | K21: 100186
A22: 21 | B22: ЯТТ 537852647 Акрамов | C22: керакмас | K22: 100186
A23: 22 | B23: "MCHJ "METCOM" VAKOLATXONASI" ИНН: 207285442, | K23: 100186

Sheet KPI
A2: № | B2: НАИМЕНОВАНИЯ | C2: Бухгалтер | D2: bank klient | E2: Столбец7 | F2: Назоратчи | G2: Ishga vaqtida kelish ketish | H2: Ishga kelish bank klient | I2: Ishga kelish nazoratchi2 | J2: Gruppa buxgalter | K2: Gruppa bank klient | L2: Didox | M2: xatlar | N2: мехнат | O2: 1c | P2: Avtokameral | Q2: Pul oqimlari | R2: Chiqadigan soliqlar | S2: Hisoblangan oylik | T2: Debitor kreditor | U2: Foyda va zarar | V2: Nazoratchi | W2: Ishga vaqtida kelish nazoratchi | X2: Ishga vaqtida kelish ketish2 | Y2: Ishga kelish bank klient3 | Z2: Gruppa buxgalter4 | AA2: Gruppa bank klient 2 | AB2: 1C baza3 | AC2: xatlar4 | AD2: Belgilangan otchetlar5 | AE2: Nazoratchi2 | AF2: NazoratchiKPI | AG2: Buxgalter KPI | AH2: Bank klient KPI
A3: 1 | B3: MONTAJ TEPLO ENERGO MCHJ | C3: Otabek | D3: Azizbek | E3: 500000 | F3: Muslimbek | H3: 1 | J3: 1 | K3: 1 | L3: 0.25 | M3: 0.25 | O3: 1 | P3: 0.25 | Q3: 0.2 | R3: 0.2 | S3: 0.2 | T3: 0.2 | U3: 0.2 | V3: 0.5 | W3: =Таблица32[[#This Row],[Столбец7]]*Таблица32[[#This Row],[Ishga kelish nazoratchi2]]% -> 0 | X3: =Таблица32[[#This Row],[Столбец7]]*Таблица32[[#This Row],[Ishga vaqtida kelish ketish]]% -> 0 | Y3: =Таблица32[[#This Row],[Столбец7]]*Таблица32[[#This Row],[Ishga kelish bank klient]]% -> 5000 | Z3: =Таблица32[[#This Row],[Столбец7]]*Таблица32[[#This Row],[Gruppa buxgalter]]% -> 5000 | AA3: =Таблица32[[#This Row],[Столбец7]]*Таблица32[[#This Row],[Gruppa bank klient ]]% -> 5000 | AB3: =Таблица32[[#This Row],[1c]]*Таблица32[[#This Row],[Столбец7]]/100 -> 5000 | AC3: =SUM(Таблица32[[#This Row],[Didox]:[ мехнат]],Таблица32[[#This Row],[Avtokameral]])*Таблица32[[#This Row],[Столбец7]]/100 -> 3750 | AD3: =SUM(Таблица32[[#This Row],[Pul oqimlari]:[Foyda va zarar]])*Таблица32[[#This Row],[Столбец7]]/100 -> 5000 | AE3: =Таблица32[[#This Row],[Столбец7]]*Таблица32[[#This Row],[Nazoratchi]]% -> 2500 | AF3: =Таблица32[[#This Row],[Ishga vaqtida kelish nazoratchi]]+Таблица32[[#This Row],[Nazoratchi2]] -> 2500 | AG3: =Таблица32[[#This Row],[Ishga vaqtida kelish ketish2]]+Таблица32[[#This Row],[Gruppa buxgalter4]]+Таблица32[[#This Row],[1C baza3]]+Таблица32[[#This Row],[xatlar4]]+Таблица32[[#This Row],[Belgilangan otchetlar5]] -> 18750 | AH3: =Таблица32[[#This Row],[Ishga kelish bank klient3]]+Таблица32[[#This Row],[Gruppa bank klient 2]] -> 10000
A4: 2 | B4: "FINANCE COUNCIL" MCHJ | C4: Ruslan | D4: Ruslan | E4: 700000 | F4: Go'zaloy | H4: 1 | K4: 1 | L4: -0.25 | M4: 0.25 | N4: 0.25 | P4: 0.25 | Q4: 0 | R4: 0 | S4: 0 | T4: 0 | U4: 0 | W4: =Таблица32[[#This Row],[Столбец7]]*Таблица32[[#This Row],[Ishga kelish nazoratchi2]]% -> 0 | X4: =Таблица32[[#This Row],[Столбец7]]*Таблица32[[#This Row],[Ishga vaqtida kelish ketish]]% -> 0 | Y4: =Таблица32[[#This Row],[Столбец7]]*Таблица32[[#This Row],[Ishga kelish bank klient]]% -> 7000 | Z4: =Таблица32[[#This Row],[Столбец7]]*Таблица32[[#This Row],[Gruppa buxgalter]]% -> 0 | AA4: =Таблица32[[#This Row],[Столбец7]]*Таблица32[[#This Row],[Gruppa bank klient ]]% -> 7000 | AB4: =Таблица32[[#This Row],[1c]]*Таблица32[[#This Row],[Столбец7]]/100 -> 0 | AC4: =SUM(Таблица32[[#This Row],[Didox]:[ мехнат]],Таблица32[[#This Row],[Avtokameral]])*Таблица32[[#This Row],[Столбец7]]/100 -> 3500 | AD4: =SUM(Таблица32[[#This Row],[Pul oqimlari]:[Foyda va zarar]])*Таблица32[[#This Row],[Столбец7]]/100 -> 0 | AE4: =Таблица32[[#This Row],[Столбец7]]*Таблица32[[#This Row],[Nazoratchi]]% -> 0 | AF4: =Таблица32[[#This Row],[Ishga vaqtida kelish nazoratchi]]+Таблица32[[#This Row],[Nazoratchi2]] -> 0 | AG4: =Таблица32[[#This Row],[Ishga vaqtida kelish ketish2]]+Таблица32[[#This Row],[Gruppa buxgalter4]]+Таблица32[[#This Row],[1C baza3]]+Таблица32[[#This Row],[xatlar4]]+Таблица32[[#This Row],[Belgilangan otchetlar5]] -> 3500 | AH4: =Таблица32[[#This Row],[Ishga kelish bank klient3]]+Таблица32[[#This Row],[Gruppa bank klient 2]] -> 14000
A5: 3 | B5: "ЧП "ROAD RIDERS" | C5: Abrorbek | D5: Ruslan | E5: 700000 | F5: Go'zaloy | H5: 1 | J5: 1 | K5: -0.5 | L5: 0.25 | M5: 0.25 | P5: 0.25 | Q5: 0 | R5: 0.2 | S5: 0.2 | T5: 0.2 | U5: 0 | V5: 0.5 | W5: =Таблица32[[#This Row],[Столбец7]]*Таблица32[[#This Row],[Ishga kelish nazoratchi2]]% -> 0 | X5: =Таблица32[[#This Row],[Столбец7]]*Таблица32[[#This Row],[Ishga vaqtida kelish ketish]]% -> 0 | Y5: =Таблица32[[#This Row],[Столбец7]]*Таблица32[[#This Row],[Ishga kelish bank klient]]% -> 7000 | Z5: =Таблица32[[#This Row],[Столбец7]]*Таблица32[[#This Row],[Gruppa buxgalter]]% -> 7000 | AA5: =Таблица32[[#This Row],[Столбец7]]*Таблица32[[#This Row],[Gruppa bank klient ]]% -> -3500 | AB5: =Таблица32[[#This Row],[1c]]*Таблица32[[#This Row],[Столбец7]]/100 -> 0 | AC5: =SUM(Таблица32[[#This Row],[Didox]:[ мехнат]],Таблица32[[#This Row],[Avtokameral]])*Таблица32[[#This Row],[Столбец7]]/100 -> 5250 | AD5: =SUM(Таблица32[[#This Row],[Pul oqimlari]:[Foyda va zarar]])*Таблица32[[#This Row],[Столбец7]]/100 -> 4200 | AE5: =Таблица32[[#This Row],[Столбец7]]*Таблица32[[#This Row],[Nazoratchi]]% -> 3500 | AF5: =Таблица32[[#This Row],[Ishga vaqtida kelish nazoratchi]]+Таблица32[[#This Row],[Nazoratchi2]] -> 3500 | AG5: =Таблица32[[#This Row],[Ishga vaqtida kelish ketish2]]+Таблица32[[#This Row],[Gruppa buxgalter4]]+Таблица32[[#This Row],[1C baza3]]+Таблица32[[#This Row],[xatlar4]]+Таблица32[[#This Row],[Belgilangan otchetlar5]] -> 16450 | AH5: =Таблица32[[#This Row],[Ishga kelish bank klient3]]+Таблица32[[#This Row],[Gruppa bank klient 2]] -> 3500
A6: 4 | B6: ЧП "SEVEN`S UP" | C6: Ruslan | D6: Ruslan | E6: 700000 | F6: Go'zaloy | H6: 1 | K6: 1 | L6: 0.25 | M6: 0.25 | N6: 0.25 | P6: 0.25 | Q6: 0 | R6: 0 | S6: 0 | T6: 0 | U6: 0 | W6: =Таблица32[[#This Row],[Столбец7]]*Таблица32[[#This Row],[Ishga kelish nazoratchi2]]% -> 0 | X6: =Таблица32[[#This Row],[Столбец7]]*Таблица32[[#This Row],[Ishga vaqtida kelish ketish]]% -> 0 | Y6: =Таблица32[[#This Row],[Столбец7]]*Таблица32[[#This Row],[Ishga kelish bank klient]]% -> 7000 | Z6: =Таблица32[[#This Row],[Столбец7]]*Таблица32[[#This Row],[Gruppa buxgalter]]% -> 0 | AA6: =Таблица32[[#This Row],[Столбец7]]*Таблица32[[#This Row],[Gruppa bank klient ]]% -> 7000 | AB6: =Таблица32[[#This Row],[1c]]*Таблица32[[#This Row],[Столбец7]]/100 -> 0 | AC6: =SUM(Таблица32[[#This Row],[Didox]:[ мехнат]],Таблица32[[#This Row],[Avtokameral]])*Таблица32[[#This Row],[Столбец7]]/100 -> 7000 | AD6: =SUM(Таблица32[[#This Row],[Pul oqimlari]:[Foyda va zarar]])*Таблица32[[#This Row],[Столбец7]]/100 -> 0 | AE6: =Таблица32[[#This Row],[Столбец7]]*Таблица32[[#This Row],[Nazoratchi]]% -> 0 | AF6: =Таблица32[[#This Row],[Ishga vaqtida kelish nazoratchi]]+Таблица32[[#This Row],[Nazoratchi2]] -> 0 | AG6: =Таблица32[[#This Row],[Ishga vaqtida kelish ketish2]]+Таблица32[[#This Row],[Gruppa buxgalter4]]+Таблица32[[#This Row],[1C baza3]]+Таблица32[[#This Row],[xatlar4]]+Таблица32[[#This Row],[Belgilangan otchetlar5]] -> 7000 | AH6: =Таблица32[[#This Row],[Ishga kelish bank klient3]]+Таблица32[[#This Row],[Gruppa bank klient 2]] -> 14000
A7: 5 | B7: ООО "TEN BRANCHES" | C7: Go'zaloy | E7: 0 | F7: Muslimbek | G7: 0.05 | J7: 1 | L7: 0 | M7: 0 | P7: 0 | Q7: 0 | R7: 0 | S7: 0 | T7: 0 | U7: 0 | V7: 0.5 | W7: =Таблица32[[#This Row],[Столбец7]]*Таблица32[[#This Row],[Ishga kelish nazoratchi2]]% -> 0 | X7: =Таблица32[[#This Row],[Столбец7]]*Таблица32[[#This Row],[Ishga vaqtida kelish ketish]]% -> 0 | Y7: =Таблица32[[#This Row],[Столбец7]]*Таблица32[[#This Row],[Ishga kelish bank klient]]% -> 0 | Z7: =Таблица32[[#This Row],[Столбец7]]*Таблица32[[#This Row],[Gruppa buxgalter]]% -> 0 | AA7: =Таблица32[[#This Row],[Столбец7]]*Таблица32[[#This Row],[Gruppa bank klient ]]% -> 0 | AB7: =Таблица32[[#This Row],[1c]]*Таблица32[[#This Row],[Столбец7]]/100 -> 0 | AC7: =SUM(Таблица32[[#This Row],[Didox]:[ мехнат]],Таблица32[[#This Row],[Avtokameral]])*Таблица32[[#This Row],[Столбец7]]/100 -> 0 | AD7: =SUM(Таблица32[[#This Row],[Pul oqimlari]:[Foyda va zarar]])*Таблица32[[#This Row],[Столбец7]]/100 -> 0 | AE7: =Таблица32[[#This Row],[Столбец7]]*Таблица32[[#This Row],[Nazoratchi]]% -> 0 | AF7: =Таблица32[[#This Row],[Ishga vaqtida kelish nazoratchi]]+Таблица32[[#This Row],[Nazoratchi2]] -> 0 | AG7: =Таблица32[[#This Row],[Ishga vaqtida kelish ketish2]]+Таблица32[[#This Row],[Gruppa buxgalter4]]+Таблица32[[#This Row],[1C baza3]]+Таблица32[[#This Row],[xatlar4]]+Таблица32[[#This Row],[Belgilangan otchetlar5]] -> 0 | AH7: =Таблица32[[#This Row],[Ishga kelish bank klient3]]+Таблица32[[#This Row],[Gruppa bank klient 2]] -> 0
A8: 6 | B8: СП "ZIL-BAX" | C8: Abrorbek | D8: Ruslan | E8: 700000 | F8: Go'zaloy | H8: 1 | J8: 1 | K8: 1 | L8: 0.25 | M8: 0.25 | P8: 0.25 | Q8: 0 | R8: 0.2 | S8: 0.2 | T8: 0.2 | U8: 0 | V8: 0.5 | W8: =Таблица32[[#This Row],[Столбец7]]*Таблица32[[#This Row],[Ishga kelish nazoratchi2]]% -> 0 | X8: =Таблица32[[#This Row],[Столбец7]]*Таблица32[[#This Row],[Ishga vaqtida kelish ketish]]% -> 0 | Y8: =Таблица32[[#This Row],[Столбец7]]*Таблица32[[#This Row],[Ishga kelish bank klient]]% -> 7000 | Z8: =Таблица32[[#This Row],[Столбец7]]*Таблица32[[#This Row],[Gruppa buxgalter]]% -> 7000 | AA8: =Таблица32[[#This Row],[Столбец7]]*Таблица32[[#This Row],[Gruppa bank klient ]]% -> 7000 | AB8: =Таблица32[[#This Row],[1c]]*Таблица32[[#This Row],[Столбец7]]/100 -> 0 | AC8: =SUM(Таблица32[[#This Row],[Didox]:[ мехнат]],Таблица32[[#This Row],[Avtokameral]])*Таблица32[[#This Row],[Столбец7]]/100 -> 5250 | AD8: =SUM(Таблица32[[#This Row],[Pul oqimlari]:[Foyda va zarar]])*Таблица32[[#This Row],[Столбец7]]/100 -> 4200 | AE8: =Таблица32[[#This Row],[Столбец7]]*Таблица32[[#This Row],[Nazoratchi]]% -> 3500 | AF8: =Таблица32[[#This Row],[Ishga vaqtida kelish nazoratchi]]+Таблица32[[#This Row],[Nazoratchi2]] -> 3500 | AG8: =Таблица32[[#This Row],[Ishga vaqtida kelish ketish2]]+Таблица32[[#This Row],[Gruppa buxgalter4]]+Таблица32[[#This Row],[1C baza3]]+Таблица32[[#This Row],[xatlar4]]+Таблица32[[#This Row],[Belgilangan otchetlar5]] -> 16450 | AH8: =Таблица32[[#This Row],[Ishga kelish bank klient3]]+Таблица32[[#This Row],[Gruppa bank klient 2]] -> 14000
A9: 7 | B9: OOO "SARDORBEK HOUSE" | C9: Ruslan | D9: Ruslan | E9: 700000 | F9: Go'zaloy | H9: 1 | K9: 1 | L9: 0.25 | M9: 0.25 | P9: 0.25 | Q9: 0 | R9: 0 | S9: 0 | T9: 0 | U9: 0 | W9: =Таблица32[[#This Row],[Столбец7]]*Таблица32[[#This Row],[Ishga kelish nazoratchi2]]% -> 0 | X9: =Таблица32[[#This Row],[Столбец7]]*Таблица32[[#This Row],[Ishga vaqtida kelish ketish]]% -> 0 | Y9: =Таблица32[[#This Row],[Столбец7]]*Таблица32[[#This Row],[Ishga kelish bank klient]]% -> 7000 | Z9: =Таблица32[[#This Row],[Столбец7]]*Таблица32[[#This Row],[Gruppa buxgalter]]% -> 0 | AA9: =Таблица32[[#This Row],[Столбец7]]*Таблица32[[#This Row],[Gruppa bank klient ]]% -> 7000 | AB9: =Таблица32[[#This Row],[1c]]*Таблица32[[#This Row],[Столбец7]]/100 -> 0 | AC9: =SUM(Таблица32[[#This Row],[Didox]:[ мехнат]],Таблица32[[#This Row],[Avtokameral]])*Таблица32[[#This Row],[Столбец7]]/100 -> 5250 | AD9: =SUM(Таблица32[[#This Row],[Pul oqimlari]:[Foyda va zarar]])*Таблица32[[#This Row],[Столбец7]]/100 -> 0 | AE9: =Таблица32[[#This Row],[Столбец7]]*Таблица32[[#This Row],[Nazoratchi]]% -> 0 | AF9: =Таблица32[[#This Row],[Ishga vaqtida kelish nazoratchi]]+Таблица32[[#This Row],[Nazoratchi2]] -> 0 | AG9: =Таблица32[[#This Row],[Ishga vaqtida kelish ketish2]]+Таблица32[[#This Row],[Gruppa buxgalter4]]+Таблица32[[#This Row],[1C baza3]]+Таблица32[[#This Row],[xatlar4]]+Таблица32[[#This Row],[Belgilangan otchetlar5]] -> 5250 | AH9: =Таблица32[[#This Row],[Ishga kelish bank klient3]]+Таблица32[[#This Row],[Gruppa bank klient 2]] -> 14000
A10: 8 | B10: "DILFUZAXON AVTO" | C10: Abrorbek | D10: Ruslan | E10: 2000000 | F10: Go'zaloy | H10: 1 | J10: -2 | K10: 1 | L10: 0.25 | M10: 0.25 | P10: -0.25 | Q10: 0 | R10: 0.2 | S10: 0.2 | T10: 0.2 | U10: 0.2 | V10: -2 | W10: =Таблица32[[#This Row],[Столбец7]]*Таблица32[[#This Row],[Ishga kelish nazoratchi2]]% -> 0 | X10: =Таблица32[[#This Row],[Столбец7]]*Таблица32[[#This Row],[Ishga vaqtida kelish ketish]]% -> 0 | Y10: =Таблица32[[#This Row],[Столбец7]]*Таблица32[[#This Row],[Ishga kelish bank klient]]% -> 20000 | Z10: =Таблица32[[#This Row],[Столбец7]]*Таблица32[[#This Row],[Gruppa buxgalter]]% -> -40000 | AA10: =Таблица32[[#This Row],[Столбец7]]*Таблица32[[#This Row],[Gruppa bank klient ]]% -> 20000 | AB10: =Таблица32[[#This Row],[1c]]*Таблица32[[#This Row],[Столбец7]]/100 -> 0 | AC10: =SUM(Таблица32[[#This Row],[Didox]:[ мехнат]],Таблица32[[#This Row],[Avtokameral]])*Таблица32[[#This Row],[Столбец7]]/100 -> 5000 | AD10: =SUM(Таблица32[[#This Row],[Pul oqimlari]:[Foyda va zarar]])*Таблица32[[#This Row],[Столбец7]]/100 -> 16000 | AE10: =Таблица32[[#This Row],[Столбец7]]*Таблица32[[#This Row],[Nazoratchi]]% -> -40000 | AF10: =Таблица32[[#This Row],[Ishga vaqtida kelish nazoratchi]]+Таблица32[[#This Row],[Nazoratchi2]] -> -40000 | AG10: =Таблица32[[#This Row],[Ishga vaqtida kelish ketish2]]+Таблица32[[#This Row],[Gruppa buxgalter4]]+Таблица32[[#This Row],[1C baza3]]+Таблица32[[#This Row],[xatlar4]]+Таблица32[[#This Row],[Belgilangan otchetlar5]] -> -19000 | AH10: =Таблица32[[#This Row],[Ishga kelish bank klient3]]+Таблица32[[#This Row],[Gruppa bank klient 2]] -> 40000
A11: 9 | B11: "SOF MEDTEX" MCHJ | C11: Maxmuda | D11: Azizbek | E11: 6000000 | F11: Go'zaloy | H11: 1 | J11: 1 | K11: 1 | L11: 0.25 | M11: 0.25 | N11: 0.25 | P11: 0.25 | Q11: -0.2 | R11: 0.2 | S11: -0.2 | T11: -0.2 | U11: -0.2 | V11: 0.5 | W11: =Таблица32[[#This Row],[Столбец7]]*Таблица32[[#This Row],[Ishga kelish nazoratchi2]]% -> 0 | X11: =Таблица32[[#This Row],[Столбец7]]*Таблица32[[#This Row],[Ishga vaqtida kelish ketish]]% -> 0 | Y11: =Таблица32[[#This Row],[Столбец7]]*Таблица32[[#This Row],[Ishga kelish bank klient]]% -> 60000 | Z11: =Таблица32[[#This Row],[Столбец7]]*Таблица32[[#This Row],[Gruppa buxgalter]]% -> 60000 | AA11: =Таблица32[[#This Row],[Столбец7]]*Таблица32[[#This Row],[Gruppa bank klient ]]% -> 60000 | AB11: =Таблица32[[#This Row],[1c]]*Таблица32[[#This Row],[Столбец7]]/100 -> 0 | AC11: =SUM(Таблица32[[#This Row],[Didox]:[ мехнат]],Таблица32[[#This Row],[Avtokameral]])*Таблица32[[#This Row],[Столбец7]]/100 -> 60000 | AD11: =SUM(Таблица32[[#This Row],[Pul oqimlari]:[Foyda va zarar]])*Таблица32[[#This Row],[Столбец7]]/100 -> -36000 | AE11: =Таблица32[[#This Row],[Столбец7]]*Таблица32[[#This Row],[Nazoratchi]]% -> 30000 | AF11: =Таблица32[[#This Row],[Ishga vaqtida kelish nazoratchi]]+Таблица32[[#This Row],[Nazoratchi2]] -> 30000 | AG11: =Таблица32[[#This Row],[Ishga vaqtida kelish ketish2]]+Таблица32[[#This Row],[Gruppa buxgalter4]]+Таблица32[[#This Row],[1C baza3]]+Таблица32[[#This Row],[xatlar4]]+Таблица32[[#This Row],[Belgilangan otchetlar5]] -> 84000 | AH11: =Таблица32[[#This Row],[Ishga kelish bank klient3]]+Таблица32[[#This Row],[Gruppa bank klient 2]] -> 120000
A12: 10 | B12: OOO "RONICS" | C12: Muslimbek | D12: Azizbek | E12: 2500000 | F12: Go'zaloy | G12: -0.8 | H12: 1 | J12: -0.5 | K12: 1 | L12: 0.25 | M12: 0.25 | O12: 1 | P12: 0 | Q12: 0.2 | R12: 0.2 | S12: 0.2 | T12: 0.2 | U12: 0.2 | V12: -0.5 | W12: =Таблица32[[#This Row],[Столбец7]]*Таблица32[[#This Row],[Ishga kelish nazoratchi2]]% -> 0 | X12: =Таблица32[[#This Row],[Столбец7]]*Таблица32[[#This Row],[Ishga vaqtida kelish ketish]]% -> -20000 | Y12: =Таблица32[[#This Row],[Столбец7]]*Таблица32[[#This Row],[Ishga kelish bank klient]]% -> 25000 | Z12: =Таблица32[[#This Row],[Столбец7]]*Таблица32[[#This Row],[Gruppa buxgalter]]% -> -12500 | AA12: =Таблица32[[#This Row],[Столбец7]]*Таблица32[[#This Row],[Gruppa bank klient ]]% -> 25000 | AB12: =Таблица32[[#This Row],[1c]]*Таблица32[[#This Row],[Столбец7]]/100 -> 25000 | AC12: =SUM(Таблица32[[#This Row],[Didox]:[ мехнат]],Таблица32[[#This Row],[Avtokameral]])*Таблица32[[#This Row],[Столбец7]]/100 -> 12500 | AD12: =SUM(Таблица32[[#This Row],[Pul oqimlari]:[Foyda va zarar]])*Таблица32[[#This Row],[Столбец7]]/100 -> 25000 | AE12: =Таблица32[[#This Row],[Столбец7]]*Таблица32[[#This Row],[Nazoratchi]]% -> -12500 | AF12: =Таблица32[[#This Row],[Ishga vaqtida kelish nazoratchi]]+Таблица32[[#This Row],[Nazoratchi2]] -> -12500 | AG12: =Таблица32[[#This Row],[Ishga vaqtida kelish ketish2]]+Таблица32[[#This Row],[Gruppa buxgalter4]]+Таблица32[[#This Row],[1C baza3]]+Таблица32[[#This Row],[xatlar4]]+Таблица32[[#This Row],[Belgilangan otchetlar5]] -> 30000 | AH12: =Таблица32[[#This Row],[Ishga kelish bank klient3]]+Таблица32[[#This Row],[Gruppa bank klient 2]] -> 50000
A13: 11 | B13: "SAPRAMTECH" OOO | C13: Muslimbek | D13: Azizbek | E13: 7000000 | F13: Go'zaloy | G13: -0.8 | H13: 1 | J13: -0.5 | K13: 1 | L13: 0.25 | M13: 0.25 | N13: 0.25 | O13: 1 | P13: 0 | Q13: 0.2 | R13: 0.2 | S13: 0.2 | T13: 0.2 | U13: 0.2 | V13: -0.5 | W13: =Таблица32[[#This Row],[Столбец7]]*Таблица32[[#This Row],[Ishga kelish nazoratchi2]]% -> 0 | X13: =Таблица32[[#This Row],[Столбец7]]*Таблица32[[#This Row],[Ishga vaqtida kelish ketish]]% -> -56000 | Y13: =Таблица32[[#This Row],[Столбец7]]*Таблица32[[#This Row],[Ishga kelish bank klient]]% -> 70000 | Z13: =Таблица32[[#This Row],[Столбец7]]*Таблица32[[#This Row],[Gruppa buxgalter]]% -> -35000 | AA13: =Таблица32[[#This Row],[Столбец7]]*Таблица32[[#This Row],[Gruppa bank klient ]]% -> 70000 | AB13: =Таблица32[[#This Row],[1c]]*Таблица32[[#This Row],[Столбец7]]/100 -> 70000 | AC13: =SUM(Таблица32[[#This Row],[Didox]:[ мехнат]],Таблица32[[#This Row],[Avtokameral]])*Таблица32[[#This Row],[Столбец7]]/100 -> 52500 | AD13: =SUM(Таблица32[[#This Row],[Pul oqimlari]:[Foyda va zarar]])*Таблица32[[#This Row],[Столбец7]]/100 -> 70000 | AE13: =Таблица32[[#This Row],[Столбец7]]*Таблица32[[#This Row],[Nazoratchi]]% -> -35000 | AF13: =Таблица32[[#This Row],[Ishga vaqtida kelish nazoratchi]]+Таблица32[[#This Row],[Nazoratchi2]] -> -35000 | AG13: =Таблица32[[#This Row],[Ishga vaqtida kelish ketish2]]+Таблица32[[#This Row],[Gruppa buxgalter4]]+Таблица32[[#This Row],[1C baza3]]+Таблица32[[#This Row],[xatlar4]]+Таблица32[[#This Row],[Belgilangan otchetlar5]] -> 101500 | AH13: =Таблица32[[#This Row],[Ishga kelish bank klient3]]+Таблица32[[#This Row],[Gruppa bank klient 2]] -> 140000
A14: 12 | B14: GELECTRONIC | C14: Mirabbos | D14: Ruslan | E14: 4000000 | F14: Muslimbek | H14: 1 | J14: 1 | K14: 1 | L14: 0.25 | M14: 0.25 | N14: 0.25 | P14: 0.25 | Q14: 0.2 | R14: 0.2 | S14: 0.2 | T14: 0.2 | U14: 0.2 | V14: 0.5 | W14: =Таблица32[[#This Row],[Столбец7]]*Таблица32[[#This Row],[Ishga kelish nazoratchi2]]% -> 0 | X14: =Таблица32[[#This Row],[Столбец7]]*Таблица32[[#This Row],[Ishga vaqtida kelish ketish]]% -> 0 | Y14: =Таблица32[[#This Row],[Столбец7]]*Таблица32[[#This Row],[Ishga kelish bank klient]]% -> 40000 | Z14: =Таблица32[[#This Row],[Столбец7]]*Таблица32[[#This Row],[Gruppa buxgalter]]% -> 40000 | AA14: =Таблица32[[#This Row],[Столбец7]]*Таблица32[[#This Row],[Gruppa bank klient ]]% -> 40000 | AB14: =Таблица32[[#This Row],[1c]]*Таблица32[[#This Row],[Столбец7]]/100 -> 0 | AC14: =SUM(Таблица32[[#This Row],[Didox]:[ мехнат]],Таблица32[[#This Row],[Avtokameral]])*Таблица32[[#This Row],[Столбец7]]/100 -> 40000 | AD14: =SUM(Таблица32[[#This Row],[Pul oqimlari]:[Foyda va zarar]])*Таблица32[[#This Row],[Столбец7]]/100 -> 40000 | AE14: =Таблица32[[#This Row],[Столбец7]]*Таблица32[[#This Row],[Nazoratchi]]% -> 20000 | AF14: =Таблица32[[#This Row],[Ishga vaqtida kelish nazoratchi]]+Таблица32[[#This Row],[Nazoratchi2]] -> 20000 | AG14: =Таблица32[[#This Row],[Ishga vaqtida kelish ketish2]]+Таблица32[[#This Row],[Gruppa buxgalter4]]+Таблица32[[#This Row],[1C baza3]]+Таблица32[[#This Row],[xatlar4]]+Таблица32[[#This Row],[Belgilangan otchetlar5]] -> 120000 | AH14: =Таблица32[[#This Row],[Ishga kelish bank klient3]]+Таблица32[[#This Row],[Gruppa bank klient 2]] -> 80000
A15: 13 | B15: SHIRIN XK | C15: Go'zaloy | E15: 2000000 | F15: Muslimbek | G15: 0.05 | J15: 1 | L15: 0.25 | M15: 0.25 | N15: 0.25 | O15: 1 | P15: 0.25 | Q15: 0.2 | R15: 0.2 | S15: 0.2 | T15: 0.2 | U15: 0.2 | V15: 0.5 | W15: =Таблица32[[#This Row],[Столбец7]]*Таблица32[[#This Row],[Ishga kelish nazoratchi2]]% -> 0 | X15: =Таблица32[[#This Row],[Столбец7]]*Таблица32[[#This Row],[Ishga vaqtida kelish ketish]]% -> 1000 | Y15: =Таблица32[[#This Row],[Столбец7]]*Таблица32[[#This Row],[Ishga kelish bank klient]]% -> 0 | Z15: =Таблица32[[#This Row],[Столбец7]]*Таблица32[[#This Row],[Gruppa buxgalter]]% -> 20000 | AA15: =Таблица32[[#This Row],[Столбец7]]*Таблица32[[#This Row],[Gruppa bank klient ]]% -> 0 | AB15: =Таблица32[[#This Row],[1c]]*Таблица32[[#This Row],[Столбец7]]/100 -> 20000 | AC15: =SUM(Таблица32[[#This Row],[Didox]:[ мехнат]],Таблица32[[#This Row],[Avtokameral]])*Таблица32[[#This Row],[Столбец7]]/100 -> 20000 | AD15: =SUM(Таблица32[[#This Row],[Pul oqimlari]:[Foyda va zarar]])*Таблица32[[#This Row],[Столбец7]]/100 -> 20000 | AE15: =Таблица32[[#This Row],[Столбец7]]*Таблица32[[#This Row],[Nazoratchi]]% -> 10000 | AF15: =Таблица32[[#This Row],[Ishga vaqtida kelish nazoratchi]]+Таблица32[[#This Row],[Nazoratchi2]] -> 10000 | AG15: =Таблица32[[#This Row],[Ishga vaqtida kelish ketish2]]+Таблица32[[#This Row],[Gruppa buxgalter4]]+Таблица32[[#This Row],[1C baza3]]+Таблица32[[#This Row],[xatlar4]]+Таблица32[[#This Row],[Belgilangan otchetlar5]] -> 81000 | AH15: =Таблица32[[#This Row],[Ishga kelish bank klient3]]+Таблица32[[#This Row],[Gruppa bank klient 2]] -> 0
A16: 14 | B16: MELIOMASH | C16: Go'zaloy | E16: 0 | F16: Muslimbek | G16: 0.05 | J16: 1 | L16: 0 | M16: 0 | P16: 0 | Q16: 0 | R16: 0 | S16: 0 | T16: 0 | U16: 0 | V16: 0.5 | W16: =Таблица32[[#This Row],[Столбец7]]*Таблица32[[#This Row],[Ishga kelish nazoratchi2]]% -> 0 | X16: =Таблица32[[#This Row],[Столбец7]]*Таблица32[[#This Row],[Ishga vaqtida kelish ketish]]% -> 0 | Y16: =Таблица32[[#This Row],[Столбец7]]*Таблица32[[#This Row],[Ishga kelish bank klient]]% -> 0 | Z16: =Таблица32[[#This Row],[Столбец7]]*Таблица32[[#This Row],[Gruppa buxgalter]]% -> 0 | AA16: =Таблица32[[#This Row],[Столбец7]]*Таблица32[[#This Row],[Gruppa bank klient ]]% -> 0 | AB16: =Таблица32[[#This Row],[1c]]*Таблица32[[#This Row],[Столбец7]]/100 -> 0 | AC16: =SUM(Таблица32[[#This Row],[Didox]:[ мехнат]],Таблица32[[#This Row],[Avtokameral]])*Таблица32[[#This Row],[Столбец7]]/100 -> 0 | AD16: =SUM(Таблица32[[#This Row],[Pul oqimlari]:[Foyda va zarar]])*Таблица32[[#This Row],[Столбец7]]/100 -> 0 | AE16: =Таблица32[[#This Row],[Столбец7]]*Таблица32[[#This Row],[Nazoratchi]]% -> 0 | AF16: =Таблица32[[#This Row],[Ishga vaqtida kelish nazoratchi]]+Таблица32[[#This Row],[Nazoratchi2]] -> 0 | AG16: =Таблица32[[#This Row],[Ishga vaqtida kelish ketish2]]+Таблица32[[#This Row],[Gruppa buxgalter4]]+Таблица32[[#This Row],[1C baza3]]+Таблица32[[#This Row],[xatlar4]]+Таблица32[[#This Row],[Belgilangan otchetlar5]] -> 0 | AH16: =Таблица32[[#This Row],[Ishga kelish bank klient3]]+Таблица32[[#This Row],[Gruppa bank klient 2]] -> 0
A17: 15 | B17: "C A WOLVES" | C17: Axmadjon | D17: Azizbek | E17: 3000000 | F17: Muslimbek | H17: 1 | J17: 1 | K17: 1 | L17: 0.25 | M17: 0.25 | O17: 1 | P17: 0.25 | Q17: 0.2 | R17: 0.2 | S17: 0 | T17: 0.2 | U17: 0.2 | V17: 0.5 | W17: =Таблица32[[#This Row],[Столбец7]]*Таблица32[[#This Row],[Ishga kelish nazoratchi2]]% -> 0 | X17: =Таблица32[[#This Row],[Столбец7]]*Таблица32[[#This Row],[Ishga vaqtida kelish ketish]]% -> 0 | Y17: =Таблица32[[#This Row],[Столбец7]]*Таблица32[[#This Row],[Ishga kelish bank klient]]% -> 30000 | Z17: =Таблица32[[#This Row],[Столбец7]]*Таблица32[[#This Row],[Gruppa buxgalter]]% -> 30000 | AA17: =Таблица32[[#This Row],[Столбец7]]*Таблица32[[#This Row],[Gruppa bank klient ]]% -> 30000 | AB17: =Таблица32[[#This Row],[1c]]*Таблица32[[#This Row],[Столбец7]]/100 -> 30000 | AC17: =SUM(Таблица32[[#This Row],[Didox]:[ мехнат]],Таблица32[[#This Row],[Avtokameral]])*Таблица32[[#This Row],[Столбец7]]/100 -> 22500 | AD17: =SUM(Таблица32[[#This Row],[Pul oqimlari]:[Foyda va zarar]])*Таблица32[[#This Row],[Столбец7]]/100 -> 24000 | AE17: =Таблица32[[#This Row],[Столбец7]]*Таблица32[[#This Row],[Nazoratchi]]% -> 15000 | AF17: =Таблица32[[#This Row],[Ishga vaqtida kelish nazoratchi]]+Таблица32[[#This Row],[Nazoratchi2]] -> 15000 | AG17: =Таблица32[[#This Row],[Ishga vaqtida kelish ketish2]]+Таблица32[[#This Row],[Gruppa buxgalter4]]+Таблица32[[#This Row],[1C baza3]]+Таблица32[[#This Row],[xatlar4]]+Таблица32[[#This Row],[Belgilangan otchetlar5]] -> 106500 | AH17: =Таблица32[[#This Row],[Ishga kelish bank klient3]]+Таблица32[[#This Row],[Gruppa bank klient 2]] -> 60000
A18: 16 | B18: "AL-AZIZ ACADEMY" НОУ | C18: Musobek | D18: Azizbek | E18: 3500000 | F18: Go'zaloy | G18: 0.9 | H18: 1 | J18: 1 | K18: 1 | L18: 0.25 | M18: 0.25 | P18: 0.25 | Q18: 0.2 | R18: 0.2 | S18: 0.2 | T18: -0.2 | U18: -0.2 | V18: 0.5 | W18: =Таблица32[[#This Row],[Столбец7]]*Таблица32[[#This Row],[Ishga kelish nazoratchi2]]% -> 0 | X18: =Таблица32[[#This Row],[Столбец7]]*Таблица32[[#This Row],[Ishga vaqtida kelish ketish]]% -> 31500 | Y18: =Таблица32[[#This Row],[Столбец7]]*Таблица32[[#This Row],[Ishga kelish bank klient]]% -> 35000 | Z18: =Таблица32[[#This Row],[Столбец7]]*Таблица32[[#This Row],[Gruppa buxgalter]]% -> 35000 | AA18: =Таблица32[[#This Row],[Столбец7]]*Таблица32[[#This Row],[Gruppa bank klient ]]% -> 35000 | AB18: =Таблица32[[#This Row],[1c]]*Таблица32[[#This Row],[Столбец7]]/100 -> 0 | AC18: =SUM(Таблица32[[#This Row],[Didox]:[ мехнат]],Таблица32[[#This Row],[Avtokameral]])*Таблица32[[#This Row],[Столбец7]]/100 -> 26250 | AD18: =SUM(Таблица32[[#This Row],[Pul oqimlari]:[Foyda va zarar]])*Таблица32[[#This Row],[Столбец7]]/100 -> 7000 | AE18: =Таблица32[[#This Row],[Столбец7]]*Таблица32[[#This Row],[Nazoratchi]]% -> 17500 | AF18: =Таблица32[[#This Row],[Ishga vaqtida kelish nazoratchi]]+Таблица32[[#This Row],[Nazoratchi2]] -> 17500 | AG18: =Таблица32[[#This Row],[Ishga vaqtida kelish ketish2]]+Таблица32[[#This Row],[Gruppa buxgalter4]]+Таблица32[[#This Row],[1C baza3]]+Таблица32[[#This Row],[xatlar4]]+Таблица32[[#This Row],[Belgilangan otchetlar5]] -> 99750 | AH18: =Таблица32[[#This Row],[Ishga kelish bank klient3]]+Таблица32[[#This Row],[Gruppa bank klient 2]] -> 70000
A19: 17 | B19: ООО "INTEST MAX" | C19: Go'zaloy | D19: Azizbek | E19: 25000000 | F19: Muslimbek | G19: 0.05 | H19: 1 | J19: 1 | K19: 1 | L19: 0.25 | M19: 0.25 | N19: 0.25 | O19: 1 | P19: 0.25 | Q19: 0 | R19: 0.2 | S19: 0.2 | T19: 0.2 | U19: 0 | V19: 0.5 | W19: =Таблица32[[#This Row],[Столбец7]]*Таблица32[[#This Row],[Ishga kelish nazoratchi2]]% -> 0 | X19: =Таблица32[[#This Row],[Столбец7]]*Таблица32[[#This Row],[Ishga vaqtida kelish ketish]]% -> 12500 | Y19: =Таблица32[[#This Row],[Столбец7]]*Таблица32[[#This Row],[Ishga kelish bank klient]]% -> 250000 | Z19: =Таблица32[[#This Row],[Столбец7]]*Таблица32[[#This Row],[Gruppa buxgalter]]% -> 250000 | AA19: =Таблица32[[#This Row],[Столбец7]]*Таблица32[[#This Row],[Gruppa bank klient ]]% -> 250000 | AB19: =Таблица32[[#This Row],[1c]]*Таблица32[[#This Row],[Столбец7]]/100 -> 250000 | AC19: =SUM(Таблица32[[#This Row],[Didox]:[ мехнат]],Таблица32[[#This Row],[Avtokameral]])*Таблица32[[#This Row],[Столбец7]]/100 -> 250000 | AD19: =SUM(Таблица32[[#This Row],[Pul oqimlari]:[Foyda va zarar]])*Таблица32[[#This Row],[Столбец7]]/100 -> 150000 | AE19: =Таблица32[[#This Row],[Столбец7]]*Таблица32[[#This Row],[Nazoratchi]]% -> 125000 | AF19: =Таблица32[[#This Row],[Ishga vaqtida kelish nazoratchi]]+Таблица32[[#This Row],[Nazoratchi2]] -> 125000 | AG19: =Таблица32[[#This Row],[Ishga vaqtida kelish ketish2]]+Таблица32[[#This Row],[Gruppa buxgalter4]]+Таблица32[[#This Row],[1C baza3]]+Таблица32[[#This Row],[xatlar4]]+Таблица32[[#This Row],[Belgilangan otchetlar5]] -> 912500 | AH19: =Таблица32[[#This Row],[Ishga kelish bank klient3]]+Таблица32[[#This Row],[Gruppa bank klient 2]] -> 500000
A20: 18 | B20: "AVIA GORODOK" | C20: Axmadjon | D20: Ruslan | E20: 1000000 | F20: Muslimbek | H20: 1 | J20: 1 | K20: 1 | L20: 0.25 | M20: 0.25 | N20: 0.25 | O20: 1 | P20: 0.25 | Q20: 0.2 | R20: 0.2 | S20: 0.2 | T20: 0.2 | U20: 0.2 | V20: 0.5 | W20: =Таблица32[[#This Row],[Столбец7]]*Таблица32[[#This Row],[Ishga kelish nazoratchi2]]% -> 0 | X20: =Таблица32[[#This Row],[Столбец7]]*Таблица32[[#This Row],[Ishga vaqtida kelish ketish]]% -> 0 | Y20: =Таблица32[[#This Row],[Столбец7]]*Таблица32[[#This Row],[Ishga kelish bank klient]]% -> 10000 | Z20: =Таблица32[[#This Row],[Столбец7]]*Таблица32[[#This Row],[Gruppa buxgalter]]% -> 10000 | AA20: =Таблица32[[#This Row],[Столбец7]]*Таблица32[[#This Row],[Gruppa bank klient ]]% -> 10000 | AB20: =Таблица32[[#This Row],[1c]]*Таблица32[[#This Row],[Столбец7]]/100 -> 10000 | AC20: =SUM(Таблица32[[#This Row],[Didox]:[ мехнат]],Таблица32[[#This Row],[Avtokameral]])*Таблица32[[#This Row],[Столбец7]]/100 -> 10000 | AD20: =SUM(Таблица32[[#This Row],[Pul oqimlari]:[Foyda va zarar]])*Таблица32[[#This Row],[Столбец7]]/100 -> 10000 | AE20: =Таблица32[[#This Row],[Столбец7]]*Таблица32[[#This Row],[Nazoratchi]]% -> 5000 | AF20: =Таблица32[[#This Row],[Ishga vaqtida kelish nazoratchi]]+Таблица32[[#This Row],[Nazoratchi2]] -> 5000 | AG20: =Таблица32[[#This Row],[Ishga vaqtida kelish ketish2]]+Таблица32[[#This Row],[Gruppa buxgalter4]]+Таблица32[[#This Row],[1C baza3]]+Таблица32[[#This Row],[xatlar4]]+Таблица32[[#This Row],[Belgilangan otchetlar5]] -> 40000 | AH20: =Таблица32[[#This Row],[Ishga kelish bank klient3]]+Таблица32[[#This Row],[Gruppa bank klient 2]] -> 20000
A21: 19 | B21: "AVTOMATLASHTIRILGAN ELEKTRIK YURITMA" | C21: Otabek | E21: 500000 | F21: Muslimbek | J21: 1 | L21: 0.25 | M21: 0.25 | P21: 0.25 | Q21: 0 | R21: 0 | S21: 0 | T21: 0 | U21: 0 | V21: 0.5 | W21: =Таблица32[[#This Row],[Столбец7]]*Таблица32[[#This Row],[Ishga kelish nazoratchi2]]% -> 0 | X21: =Таблица32[[#This Row],[Столбец7]]*Таблица32[[#This Row],[Ishga vaqtida kelish ketish]]% -> 0 | Y21: =Таблица32[[#This Row],[Столбец7]]*Таблица32[[#This Row],[Ishga kelish bank klient]]% -> 0 | Z21: =Таблица32[[#This Row],[Столбец7]]*Таблица32[[#This Row],[Gruppa buxgalter]]% -> 5000 | AA21: =Таблица32[[#This Row],[Столбец7]]*Таблица32[[#This Row],[Gruppa bank klient ]]% -> 0 | AB21: =Таблица32[[#This Row],[1c]]*Таблица32[[#This Row],[Столбец7]]/100 -> 0 | AC21: =SUM(Таблица32[[#This Row],[Didox]:[ мехнат]],Таблица32[[#This Row],[Avtokameral]])*Таблица32[[#This Row],[Столбец7]]/100 -> 3750 | AD21: =SUM(Таблица32[[#This Row],[Pul oqimlari]:[Foyda va zarar]])*Таблица32[[#This Row],[Столбец7]]/100 -> 0 | AE21: =Таблица32[[#This Row],[Столбец7]]*Таблица32[[#This Row],[Nazoratchi]]% -> 2500 | AF21: =Таблица32[[#This Row],[Ishga vaqtida kelish nazoratchi]]+Таблица32[[#This Row],[Nazoratchi2]] -> 2500 | AG21: =Таблица32[[#This Row],[Ishga vaqtida kelish ketish2]]+Таблица32[[#This Row],[Gruppa buxgalter4]]+Таблица32[[#This Row],[1C baza3]]+Таблица32[[#This Row],[xatlar4]]+Таблица32[[#This Row],[Belgilangan otchetlar5]] -> 8750 | AH21: =Таблица32[[#This Row],[Ishga kelish bank klient3]]+Таблица32[[#This Row],[Gruppa bank klient 2]] -> 0
A22: 20 | B22: BM UNIT | C22: Humora | D22: Azizbek | E22: 1000000 | F22: Go'zaloy | G22: -0.35 | H22: 1 | J22: 1 | K22: 1 | L22: 0.25 | M22: 0.25 | O22: 1 | P22: 0.25 | Q22: 0.2 | R22: 0.2 | S22: 0.2 | T22: 0.2 | U22: 0.2 | V22: 0.5 | W22: =Таблица32[[#This Row],[Столбец7]]*Таблица32[[#This Row],[Ishga kelish nazoratchi2]]% -> 0 | X22: =Таблица32[[#This Row],[Столбец7]]*Таблица32[[#This Row],[Ishga vaqtida kelish ketish]]% -> -3500 | Y22: =Таблица32[[#This Row],[Столбец7]]*Таблица32[[#This Row],[Ishga kelish bank klient]]% -> 10000 | Z22: =Таблица32[[#This Row],[Столбец7]]*Таблица32[[#This Row],[Gruppa buxgalter]]% -> 10000 | AA22: =Таблица32[[#This Row],[Столбец7]]*Таблица32[[#This Row],[Gruppa bank klient ]]% -> 10000 | AB22: =Таблица32[[#This Row],[1c]]*Таблица32[[#This Row],[Столбец7]]/100 -> 10000 | AC22: =SUM(Таблица32[[#This Row],[Didox]:[ мехнат]],Таблица32[[#This Row],[Avtokameral]])*Таблица32[[#This Row],[Столбец7]]/100 -> 7500 | AD22: =SUM(Таблица32[[#This Row],[Pul oqimlari]:[Foyda va zarar]])*Таблица32[[#This Row],[Столбец7]]/100 -> 10000 | AE22: =Таблица32[[#This Row],[Столбец7]]*Таблица32[[#This Row],[Nazoratchi]]% -> 5000 | AF22: =Таблица32[[#This Row],[Ishga vaqtida kelish nazoratchi]]+Таблица32[[#This Row],[Nazoratchi2]] -> 5000 | AG22: =Таблица32[[#This Row],[Ishga vaqtida kelish ketish2]]+Таблица32[[#This Row],[Gruppa buxgalter4]]+Таблица32[[#This Row],[1C baza3]]+Таблица32[[#This Row],[xatlar4]]+Таблица32[[#This Row],[Belgilangan otchetlar5]] -> 34000 | AH22: =Таблица32[[#This Row],[Ishga kelish bank klient3]]+Таблица32[[#This Row],[Gruppa bank klient 2]] -> 20000
A23: 21 | B23: ООО "AVTO LUXUSARY TRADE" | C23: Axmadjon | D23: Ruslan | E23: 1000000 | F23: Muslimbek | H23: 1 | J23: 1 | K23: 1 | L23: 0.25 | M23: 0.25 | O23: 1 | P23: 0.25 | Q23: 0.2 | R23: 0.2 | S23: 0.2 | T23: 0.2 | U23: 0.2 | V23: 0.5 | W23: =Таблица32[[#This Row],[Столбец7]]*Таблица32[[#This Row],[Ishga kelish nazoratchi2]]% -> 0 | X23: =Таблица32[[#This Row],[Столбец7]]*Таблица32[[#This Row],[Ishga vaqtida kelish ketish]]% -> 0 | Y23: =Таблица32[[#This Row],[Столбец7]]*Таблица32[[#This Row],[Ishga kelish bank klient]]% -> 10000 | Z23: =Таблица32[[#This Row],[Столбец7]]*Таблица32[[#This Row],[Gruppa buxgalter]]% -> 10000 | AA23: =Таблица32[[#This Row],[Столбец7]]*Таблица32[[#This Row],[Gruppa bank klient ]]% -> 10000 | AB23: =Таблица32[[#This Row],[1c]]*Таблица32[[#This Row],[Столбец7]]/100 -> 10000 | AC23: =SUM(Таблица32[[#This Row],[Didox]:[ мехнат]],Таблица32[[#This Row],[Avtokameral]])*Таблица32[[#This Row],[Столбец7]]/100 -> 7500 | AD23: =SUM(Таблица32[[#This Row],[Pul oqimlari]:[Foyda va zarar]])*Таблица32[[#This Row],[Столбец7]]/100 -> 10000 | AE23: =Таблица32[[#This Row],[Столбец7]]*Таблица32[[#This Row],[Nazoratchi]]% -> 5000 | AF23: =Таблица32[[#This Row],[Ishga vaqtida kelish nazoratchi]]+Таблица32[[#This Row],[Nazoratchi2]] -> 5000 | AG23: =Таблица32[[#This Row],[Ishga vaqtida kelish ketish2]]+Таблица32[[#This Row],[Gruppa buxgalter4]]+Таблица32[[#This Row],[1C baza3]]+Таблица32[[#This Row],[xatlar4]]+Таблица32[[#This Row],[Belgilangan otchetlar5]] -> 37500 | AH23: =Таблица32[[#This Row],[Ishga kelish bank klient3]]+Таблица32[[#This Row],[Gruppa bank klient 2]] -> 20000
A24: 22 | B24: KOLBERG PRODUCTION | E24: 50000000 | L24: 0 | M24: 0 | P24: 0 | Q24: 0 | R24: 0 | S24: 0 | T24: 0 | U24: 0 | W24: =Таблица32[[#This Row],[Столбец7]]*Таблица32[[#This Row],[Ishga kelish nazoratchi2]]% -> 0 | X24: =Таблица32[[#This Row],[Столбец7]]*Таблица32[[#This Row],[Ishga vaqtida kelish ketish]]% -> 0 | Y24: =Таблица32[[#This Row],[Столбец7]]*Таблица32[[#This Row],[Ishga kelish bank klient]]% -> 0 | Z24: =Таблица32[[#This Row],[Столбец7]]*Таблица32[[#This Row],[Gruppa buxgalter]]% -> 0 | AA24: =Таблица32[[#This Row],[Столбец7]]*Таблица32[[#This Row],[Gruppa bank klient ]]% -> 0 | AB24: =Таблица32[[#This Row],[1c]]*Таблица32[[#This Row],[Столбец7]]/100 -> 0 | AC24: =SUM(Таблица32[[#This Row],[Didox]:[ мехнат]],Таблица32[[#This Row],[Avtokameral]])*Таблица32[[#This Row],[Столбец7]]/100 -> 0 | AD24: =SUM(Таблица32[[#This Row],[Pul oqimlari]:[Foyda va zarar]])*Таблица32[[#This Row],[Столбец7]]/100 -> 0 | AE24: =Таблица32[[#This Row],[Столбец7]]*Таблица32[[#This Row],[Nazoratchi]]% -> 0 | AF24: =Таблица32[[#This Row],[Ishga vaqtida kelish nazoratchi]]+Таблица32[[#This Row],[Nazoratchi2]] -> 0 | AG24: =Таблица32[[#This Row],[Ishga vaqtida kelish ketish2]]+Таблица32[[#This Row],[Gruppa buxgalter4]]+Таблица32[[#This Row],[1C baza3]]+Таблица32[[#This Row],[xatlar4]]+Таблица32[[#This Row],[Belgilangan otchetlar5]] -> 0 | AH24: =Таблица32[[#This Row],[Ishga kelish bank klient3]]+Таблица32[[#This Row],[Gruppa bank klient 2]] -> 0
